Workbook
Name Project_Status: 'Master_Management'!$A$6:$A$12
Name Task_Status: 'Master_Management'!$B$6:$B$12
Name Priority: 'Master_Management'!$C$6:$C$9
Name Health: 'Master_Management'!$D$6:$D$11
Name Issue_Status: 'Master_Management'!$E$6:$E$11
Name Issue_Type: 'Master_Management'!$F$6:$F$11
Name Risk_Status: 'Master_Management'!$G$6:$G$10
Name Billable: 'Master_Management'!$H$6:$H$7
Name Department: 'Master_Management'!$I$6:$I$15
Name Role: 'Master_Management'!$J$6:$J$14
Name Activity_Type: 'Master_Management'!$K$6:$K$12
Name Document_Type: 'Master_Management'!$L$6:$L$13
Name UserIDs: 'Users'!$A$6:$A$300
Name TeamIDs: 'Teams'!$A$6:$A$200
Name ClientIDs: 'Clients'!$A$6:$A$200
Name ProjectIDs: 'Projects'!$A$6:$A$500
Name TaskIDs: 'Tasks'!$A$6:$A$700

Sheet Home
A1: Complete Responsive Project Management Environment
A2: Excel PMO system with desktop, compact, governance and project command views
A3: Home | B3: Exec | C3: Compact | D3: Project | E3: Tasks | F3: Kanban | G3: Gantt | H3: Reports | I3: Master
A5: Start Here
A7: Executive Dashboard | B7: Full desktop PMO dashboard
A8: Compact Dashboard | B8: Smaller-screen quick dashboard
A9: Project Command Center | B9: Single project selector view
A10: Projects | B10: Portfolio master
A11: Tasks | B11: Task tracking
A12: Kanban | B12: Status board
A13: Gantt | B13: Timeline view
A14: Change Requests | B14: Change control
A15: Approvals | B15: Approval tracker
A16: RACI Matrix | B16: Role clarity
A17: Reports | B17: PMO reports

Sheet Portfolio_Dashboard
A1: Portfolio Dashboard
A2: High-standard PMO dashboard for multiple projects
A3: Home | B3: Dashboard | C3: Workspace | D3: Projects | E3: Tasks | F3: Issues | G3: Timesheets | H3: Reports | I3: Master
A5: =COUNTA(tblProjects[Project ID]) | D5: =COUNTIFS(tblProjects[Manual Status],"In Progress") | G5: =COUNTIFS(tblProjects[Auto Health],"At Risk")+COUNTIFS(tblProjects[Auto Health],"Overdue") | J5: =COUNTIFS(tblProjects[Manual Status],"Completed")
A8: Total Projects | D8: Active Projects | G8: At Risk / Overdue | J8: Completed Projects
A10: =COUNTIFS(tblIssues[Status],"<>Closed",tblIssues[Status],"<>Resolved") | D10: =COUNTIFS(tblRisks[Status],"<>Closed") | G10: =SUM(tblTimesheets[Hours]) | J10: =SUM(tblProjects[Actual Cost])-SUM(tblProjects[Budget])
A13: Open Issues | D13: Open Risks | G13: Logged Hours | J13: Budget Variance
A16: Project Health | D16: Task Status | G16: Priority Mix | J16: User Workload
A17: Health | B17: Count | D17: Status | E17: Count | G17: Priority | H17: Count | J17: User | K17: Active Tasks
A18: On Track | B18: =COUNTIF(tblProjects[Auto Health],A18) | D18: On Track | E18: =COUNTIF(tblTasks[Auto Health],D18) | G18: Critical | H18: =COUNTIF(tblTasks[Priority],G18) | J18: =Users!B6 | K18: =Users!I6
A19: At Risk | B19: =COUNTIF(tblProjects[Auto Health],A19) | D19: At Risk | E19: =COUNTIF(tblTasks[Auto Health],D19) | G19: High | H19: =COUNTIF(tblTasks[Priority],G19) | J19: =Users!B7 | K19: =Users!I7
A20: Overdue | B20: =COUNTIF(tblProjects[Auto Health],A20) | D20: Overdue | E20: =COUNTIF(tblTasks[Auto Health],D20) | G20: Medium | H20: =COUNTIF(tblTasks[Priority],G20) | J20: =Users!B8 | K20: =Users!I8
A21: Blocked | B21: =COUNTIF(tblProjects[Auto Health],A21) | D21: Blocked | E21: =COUNTIF(tblTasks[Auto Health],D21) | G21: Low | H21: =COUNTIF(tblTasks[Priority],G21) | J21: =Users!B9 | K21: =Users!I9
A22: Completed | B22: =COUNTIF(tblProjects[Auto Health],A22) | D22: Completed | E22: =COUNTIF(tblTasks[Auto Health],D22) | J22: =Users!B10 | K22: =Users!I10
A23: Not Started | B23: =COUNTIF(tblProjects[Auto Health],A23) | D23: Not Started | E23: =COUNTIF(tblTasks[Auto Health],D23) | J23: =Users!B11 | K23: =Users!I11
A26: Portfolio List
A27: Project ID | B27: Project | C27: Status | D27: Priority | E27: Progress | F27: Health | G27: Open Issues | H27: Open Risks | I27: Hours
A28: =IFERROR(INDEX(tblProjects[Project ID],1),"") | B28: =IFERROR(INDEX(tblProjects[Project Name],1),"") | C28: =IFERROR(INDEX(tblProjects[Manual Status],1),"") | D28: =IFERROR(INDEX(tblProjects[Priority],1),"") | E28: =IFERROR(INDEX(tblProjects[Progress %],1),"") | F28: =IFERROR(INDEX(tblProjects[Auto Health],1),"") | G28: =IFERROR(INDEX(tblProjects[Open Issues],1),"") | H28: =IFERROR(INDEX(tblProjects[Open Risks],1),"") | I28: =IFERROR(INDEX(tblProjects[Logged Hours],1),"")
A29: =IFERROR(INDEX(tblProjects[Project ID],2),"") | B29: =IFERROR(INDEX(tblProjects[Project Name],2),"") | C29: =IFERROR(INDEX(tblProjects[Manual Status],2),"") | D29: =IFERROR(INDEX(tblProjects[Priority],2),"") | E29: =IFERROR(INDEX(tblProjects[Progress %],2),"") | F29: =IFERROR(INDEX(tblProjects[Auto Health],2),"") | G29: =IFERROR(INDEX(tblProjects[Open Issues],2),"") | H29: =IFERROR(INDEX(tblProjects[Open Risks],2),"") | I29: =IFERROR(INDEX(tblProjects[Logged Hours],2),"")
A30: =IFERROR(INDEX(tblProjects[Project ID],3),"") | B30: =IFERROR(INDEX(tblProjects[Project Name],3),"") | C30: =IFERROR(INDEX(tblProjects[Manual Status],3),"") | D30: =IFERROR(INDEX(tblProjects[Priority],3),"") | E30: =IFERROR(INDEX(tblProjects[Progress %],3),"") | F30: =IFERROR(INDEX(tblProjects[Auto Health],3),"") | G30: =IFERROR(INDEX(tblProjects[Open Issues],3),"") | H30: =IFERROR(INDEX(tblProjects[Open Risks],3),"") | I30: =IFERROR(INDEX(tblProjects[Logged Hours],3),"")
A31: =IFERROR(INDEX(tblProjects[Project ID],4),"") | B31: =IFERROR(INDEX(tblProjects[Project Name],4),"") | C31: =IFERROR(INDEX(tblProjects[Manual Status],4),"") | D31: =IFERROR(INDEX(tblProjects[Priority],4),"") | E31: =IFERROR(INDEX(tblProjects[Progress %],4),"") | F31: =IFERROR(INDEX(tblProjects[Auto Health],4),"") | G31: =IFERROR(INDEX(tblProjects[Open Issues],4),"") | H31: =IFERROR(INDEX(tblProjects[Open Risks],4),"") | I31: =IFERROR(INDEX(tblProjects[Logged Hours],4),"")
A32: =IFERROR(INDEX(tblProjects[Project ID],5),"") | B32: =IFERROR(INDEX(tblProjects[Project Name],5),"") | C32: =IFERROR(INDEX(tblProjects[Manual Status],5),"") | D32: =IFERROR(INDEX(tblProjects[Priority],5),"") | E32: =IFERROR(INDEX(tblProjects[Progress %],5),"") | F32: =IFERROR(INDEX(tblProjects[Auto Health],5),"") | G32: =IFERROR(INDEX(tblProjects[Open Issues],5),"") | H32: =IFERROR(INDEX(tblProjects[Open Risks],5),"") | I32: =IFERROR(INDEX(tblProjects[Logged Hours],5),"")
A33: =IFERROR(INDEX(tblProjects[Project ID],6),"") | B33: =IFERROR(INDEX(tblProjects[Project Name],6),"") | C33: =IFERROR(INDEX(tblProjects[Manual Status],6),"") | D33: =IFERROR(INDEX(tblProjects[Priority],6),"") | E33: =IFERROR(INDEX(tblProjects[Progress %],6),"") | F33: =IFERROR(INDEX(tblProjects[Auto Health],6),"") | G33: =IFERROR(INDEX(tblProjects[Open Issues],6),"") | H33: =IFERROR(INDEX(tblProjects[Open Risks],6),"") | I33: =IFERROR(INDEX(tblProjects[Logged Hours],6),"")
A34: =IFERROR(INDEX(tblProjects[Project ID],7),"") | B34: =IFERROR(INDEX(tblProjects[Project Name],7),"") | C34: =IFERROR(INDEX(tblProjects[Manual Status],7),"") | D34: =IFERROR(INDEX(tblProjects[Priority],7),"") | E34: =IFERROR(INDEX(tblProjects[Progress %],7),"") | F34: =IFERROR(INDEX(tblProjects[Auto Health],7),"") | G34: =IFERROR(INDEX(tblProjects[Open Issues],7),"") | H34: =IFERROR(INDEX(tblProjects[Open Risks],7),"") | I34: =IFERROR(INDEX(tblProjects[Logged Hours],7),"")
A35: =IFERROR(INDEX(tblProjects[Project ID],8),"") | B35: =IFERROR(INDEX(tblProjects[Project Name],8),"") | C35: =IFERROR(INDEX(tblProjects[Manual Status],8),"") | D35: =IFERROR(INDEX(tblProjects[Priority],8),"") | E35: =IFERROR(INDEX(tblProjects[Progress %],8),"") | F35: =IFERROR(INDEX(tblProjects[Auto Health],8),"") | G35: =IFERROR(INDEX(tblProjects[Open Issues],8),"") | H35: =IFERROR(INDEX(tblProjects[Open Risks],8),"") | I35: =IFERROR(INDEX(tblProjects[Logged Hours],8),"")
A36: =IFERROR(INDEX(tblProjects[Project ID],9),"") | B36: =IFERROR(INDEX(tblProjects[Project Name],9),"") | C36: =IFERROR(INDEX(tblProjects[Manual Status],9),"") | D36: =IFERROR(INDEX(tblProjects[Priority],9),"") | E36: =IFERROR(INDEX(tblProjects[Progress %],9),"") | F36: =IFERROR(INDEX(tblProjects[Auto Health],9),"") | G36: =IFERROR(INDEX(tblProjects[Open Issues],9),"") | H36: =IFERROR(INDEX(tblProjects[Open Risks],9),"") | I36: =IFERROR(INDEX(tblProjects[Logged Hours],9),"")
A37: =IFERROR(INDEX(tblProjects[Project ID],10),"") | B37: =IFERROR(INDEX(tblProjects[Project Name],10),"") | C37: =IFERROR(INDEX(tblProjects[Manual Status],10),"") | D37: =IFERROR(INDEX(tblProjects[Priority],10),"") | E37: =IFERROR(INDEX(tblProjects[Progress %],10),"") | F37: =IFERROR(INDEX(tblProjects[Auto Health],10),"") | G37: =IFERROR(INDEX(tblProjects[Open Issues],10),"") | H37: =IFERROR(INDEX(tblProjects[Open Risks],10),"") | I37: =IFERROR(INDEX(tblProjects[Logged Hours],10),"")

Sheet Project_Workspace
A1: Project Workspace
A2: Single-project command center: choose project ID in B5
A3: Home | B3: Dashboard | C3: Workspace | D3: Projects | E3: Tasks | F3: Issues | G3: Timesheets | H3: Reports | I3: Master
A5: Select Project ID | B5: PRJ-001
A7: Project Name | B7: =XLOOKUP($B$5,tblProjects[Project ID],tblProjects[Project Name],"") | D7: Manager | E7: =XLOOKUP($B$5,tblProjects[Project ID],tblProjects[Project Manager],"") | G7: Status | H7: =XLOOKUP($B$5,tblProjects[Project ID],tblProjects[Manual Status],"") | J7: Health | K7: =XLOOKUP($B$5,tblProjects[Project ID],tblProjects[Auto Health],"")
A9: Progress | B9: =XLOOKUP($B$5,tblProjects[Project ID],tblProjects[Progress %],"") | D9: Open Issues | E9: =XLOOKUP($B$5,tblProjects[Project ID],tblProjects[Open Issues],"") | G9: Open Risks | H9: =XLOOKUP($B$5,tblProjects[Project ID],tblProjects[Open Risks],"") | J9: Logged Hours | K9: =XLOOKUP($B$5,tblProjects[Project ID],tblProjects[Logged Hours],"")
A12: Project Task Snapshot
A13: Task ID | B13: Task Name | C13: Owner | D13: Status | E13: Priority | F13: Progress | G13: Health | H13: Due Date
A14: =IFERROR(INDEX(FILTER(tblTasks[Task ID],tblTasks[Project ID]=$B$5),1),"") | B14: =IFERROR(INDEX(FILTER(tblTasks[Task Name],tblTasks[Project ID]=$B$5),1),"") | C14: =IFERROR(INDEX(FILTER(tblTasks[Assigned User],tblTasks[Project ID]=$B$5),1),"") | D14: =IFERROR(INDEX(FILTER(tblTasks[Manual Status],tblTasks[Project ID]=$B$5),1),"") | E14: =IFERROR(INDEX(FILTER(tblTasks[Priority],tblTasks[Project ID]=$B$5),1),"") | F14: =IFERROR(INDEX(FILTER(tblTasks[Progress %],tblTasks[Project ID]=$B$5),1),"") | G14: =IFERROR(INDEX(FILTER(tblTasks[Auto Health],tblTasks[Project ID]=$B$5),1),"") | H14: =IFERROR(INDEX(FILTER(tblTasks[Due Date],tblTasks[Project ID]=$B$5),1),"")
A15: =IFERROR(INDEX(FILTER(tblTasks[Task ID],tblTasks[Project ID]=$B$5),2),"") | B15: =IFERROR(INDEX(FILTER(tblTasks[Task Name],tblTasks[Project ID]=$B$5),2),"") | C15: =IFERROR(INDEX(FILTER(tblTasks[Assigned User],tblTasks[Project ID]=$B$5),2),"") | D15: =IFERROR(INDEX(FILTER(tblTasks[Manual Status],tblTasks[Project ID]=$B$5),2),"") | E15: =IFERROR(INDEX(FILTER(tblTasks[Priority],tblTasks[Project ID]=$B$5),2),"") | F15: =IFERROR(INDEX(FILTER(tblTasks[Progress %],tblTasks[Project ID]=$B$5),2),"") | G15: =IFERROR(INDEX(FILTER(tblTasks[Auto Health],tblTasks[Project ID]=$B$5),2),"") | H15: =IFERROR(INDEX(FILTER(tblTasks[Due Date],tblTasks[Project ID]=$B$5),2),"")
A16: =IFERROR(INDEX(FILTER(tblTasks[Task ID],tblTasks[Project ID]=$B$5),3),"") | B16: =IFERROR(INDEX(FILTER(tblTasks[Task Name],tblTasks[Project ID]=$B$5),3),"") | C16: =IFERROR(INDEX(FILTER(tblTasks[Assigned User],tblTasks[Project ID]=$B$5),3),"") | D16: =IFERROR(INDEX(FILTER(tblTasks[Manual Status],tblTasks[Project ID]=$B$5),3),"") | E16: =IFERROR(INDEX(FILTER(tblTasks[Priority],tblTasks[Project ID]=$B$5),3),"") | F16: =IFERROR(INDEX(FILTER(tblTasks[Progress %],tblTasks[Project ID]=$B$5),3),"") | G16: =IFERROR(INDEX(FILTER(tblTasks[Auto Health],tblTasks[Project ID]=$B$5),3),"") | H16: =IFERROR(INDEX(FILTER(tblTasks[Due Date],tblTasks[Project ID]=$B$5),3),"")
A17: =IFERROR(INDEX(FILTER(tblTasks[Task ID],tblTasks[Project ID]=$B$5),4),"") | B17: =IFERROR(INDEX(FILTER(tblTasks[Task Name],tblTasks[Project ID]=$B$5),4),"") | C17: =IFERROR(INDEX(FILTER(tblTasks[Assigned User],tblTasks[Project ID]=$B$5),4),"") | D17: =IFERROR(INDEX(FILTER(tblTasks[Manual Status],tblTasks[Project ID]=$B$5),4),"") | E17: =IFERROR(INDEX(FILTER(tblTasks[Priority],tblTasks[Project ID]=$B$5),4),"") | F17: =IFERROR(INDEX(FILTER(tblTasks[Progress %],tblTasks[Project ID]=$B$5),4),"") | G17: =IFERROR(INDEX(FILTER(tblTasks[Auto Health],tblTasks[Project ID]=$B$5),4),"") | H17: =IFERROR(INDEX(FILTER(tblTasks[Due Date],tblTasks[Project ID]=$B$5),4),"")
A18: =IFERROR(INDEX(FILTER(tblTasks[Task ID],tblTasks[Project ID]=$B$5),5),"") | B18: =IFERROR(INDEX(FILTER(tblTasks[Task Name],tblTasks[Project ID]=$B$5),5),"") | C18: =IFERROR(INDEX(FILTER(tblTasks[Assigned User],tblTasks[Project ID]=$B$5),5),"") | D18: =IFERROR(INDEX(FILTER(tblTasks[Manual Status],tblTasks[Project ID]=$B$5),5),"") | E18: =IFERROR(INDEX(FILTER(tblTasks[Priority],tblTasks[Project ID]=$B$5),5),"") | F18: =IFERROR(INDEX(FILTER(tblTasks[Progress %],tblTasks[Project ID]=$B$5),5),"") | G18: =IFERROR(INDEX(FILTER(tblTasks[Auto Health],tblTasks[Project ID]=$B$5),5),"") | H18: =IFERROR(INDEX(FILTER(tblTasks[Due Date],tblTasks[Project ID]=$B$5),5),"")
A19: =IFERROR(INDEX(FILTER(tblTasks[Task ID],tblTasks[Project ID]=$B$5),6),"") | B19: =IFERROR(INDEX(FILTER(tblTasks[Task Name],tblTasks[Project ID]=$B$5),6),"") | C19: =IFERROR(INDEX(FILTER(tblTasks[Assigned User],tblTasks[Project ID]=$B$5),6),"") | D19: =IFERROR(INDEX(FILTER(tblTasks[Manual Status],tblTasks[Project ID]=$B$5),6),"") | E19: =IFERROR(INDEX(FILTER(tblTasks[Priority],tblTasks[Project ID]=$B$5),6),"") | F19: =IFERROR(INDEX(FILTER(tblTasks[Progress %],tblTasks[Project ID]=$B$5),6),"") | G19: =IFERROR(INDEX(FILTER(tblTasks[Auto Health],tblTasks[Project ID]=$B$5),6),"") | H19: =IFERROR(INDEX(FILTER(tblTasks[Due Date],tblTasks[Project ID]=$B$5),6),"")
A20: =IFERROR(INDEX(FILTER(tblTasks[Task ID],tblTasks[Project ID]=$B$5),7),"") | B20: =IFERROR(INDEX(FILTER(tblTasks[Task Name],tblTasks[Project ID]=$B$5),7),"") | C20: =IFERROR(INDEX(FILTER(tblTasks[Assigned User],tblTasks[Project ID]=$B$5),7),"") | D20: =IFERROR(INDEX(FILTER(tblTasks[Manual Status],tblTasks[Project ID]=$B$5),7),"") | E20: =IFERROR(INDEX(FILTER(tblTasks[Priority],tblTasks[Project ID]=$B$5),7),"") | F20: =IFERROR(INDEX(FILTER(tblTasks[Progress %],tblTasks[Project ID]=$B$5),7),"") | G20: =IFERROR(INDEX(FILTER(tblTasks[Auto Health],tblTasks[Project ID]=$B$5),7),"") | H20: =IFERROR(INDEX(FILTER(tblTasks[Due Date],tblTasks[Project ID]=$B$5),7),"")
A21: =IFERROR(INDEX(FILTER(tblTasks[Task ID],tblTasks[Project ID]=$B$5),8),"") | B21: =IFERROR(INDEX(FILTER(tblTasks[Task Name],tblTasks[Project ID]=$B$5),8),"") | C21: =IFERROR(INDEX(FILTER(tblTasks[Assigned User],tblTasks[Project ID]=$B$5),8),"") | D21: =IFERROR(INDEX(FILTER(tblTasks[Manual Status],tblTasks[Project ID]=$B$5),8),"") | E21: =IFERROR(INDEX(FILTER(tblTasks[Priority],tblTasks[Project ID]=$B$5),8),"") | F21: =IFERROR(INDEX(FILTER(tblTasks[Progress %],tblTasks[Project ID]=$B$5),8),"") | G21: =IFERROR(INDEX(FILTER(tblTasks[Auto Health],tblTasks[Project ID]=$B$5),8),"") | H21: =IFERROR(INDEX(FILTER(tblTasks[Due Date],tblTasks[Project ID]=$B$5),8),"")
A22: =IFERROR(INDEX(FILTER(tblTasks[Task ID],tblTasks[Project ID]=$B$5),9),"") | B22: =IFERROR(INDEX(FILTER(tblTasks[Task Name],tblTasks[Project ID]=$B$5),9),"") | C22: =IFERROR(INDEX(FILTER(tblTasks[Assigned User],tblTasks[Project ID]=$B$5),9),"") | D22: =IFERROR(INDEX(FILTER(tblTasks[Manual Status],tblTasks[Project ID]=$B$5),9),"") | E22: =IFERROR(INDEX(FILTER(tblTasks[Priority],tblTasks[Project ID]=$B$5),9),"") | F22: =IFERROR(INDEX(FILTER(tblTasks[Progress %],tblTasks[Project ID]=$B$5),9),"") | G22: =IFERROR(INDEX(FILTER(tblTasks[Auto Health],tblTasks[Project ID]=$B$5),9),"") | H22: =IFERROR(INDEX(FILTER(tblTasks[Due Date],tblTasks[Project ID]=$B$5),9),"")
A23: =IFERROR(INDEX(FILTER(tblTasks[Task ID],tblTasks[Project ID]=$B$5),10),"") | B23: =IFERROR(INDEX(FILTER(tblTasks[Task Name],tblTasks[Project ID]=$B$5),10),"") | C23: =IFERROR(INDEX(FILTER(tblTasks[Assigned User],tblTasks[Project ID]=$B$5),10),"") | D23: =IFERROR(INDEX(FILTER(tblTasks[Manual Status],tblTasks[Project ID]=$B$5),10),"") | E23: =IFERROR(INDEX(FILTER(tblTasks[Priority],tblTasks[Project ID]=$B$5),10),"") | F23: =IFERROR(INDEX(FILTER(tblTasks[Progress %],tblTasks[Project ID]=$B$5),10),"") | G23: =IFERROR(INDEX(FILTER(tblTasks[Auto Health],tblTasks[Project ID]=$B$5),10),"") | H23: =IFERROR(INDEX(FILTER(tblTasks[Due Date],tblTasks[Project ID]=$B$5),10),"")
A24: =IFERROR(INDEX(FILTER(tblTasks[Task ID],tblTasks[Project ID]=$B$5),11),"") | B24: =IFERROR(INDEX(FILTER(tblTasks[Task Name],tblTasks[Project ID]=$B$5),11),"") | C24: =IFERROR(INDEX(FILTER(tblTasks[Assigned User],tblTasks[Project ID]=$B$5),11),"") | D24: =IFERROR(INDEX(FILTER(tblTasks[Manual Status],tblTasks[Project ID]=$B$5),11),"") | E24: =IFERROR(INDEX(FILTER(tblTasks[Priority],tblTasks[Project ID]=$B$5),11),"") | F24: =IFERROR(INDEX(FILTER(tblTasks[Progress %],tblTasks[Project ID]=$B$5),11),"") | G24: =IFERROR(INDEX(FILTER(tblTasks[Auto Health],tblTasks[Project ID]=$B$5),11),"") | H24: =IFERROR(INDEX(FILTER(tblTasks[Due Date],tblTasks[Project ID]=$B$5),11),"")
A25: =IFERROR(INDEX(FILTER(tblTasks[Task ID],tblTasks[Project ID]=$B$5),12),"") | B25: =IFERROR(INDEX(FILTER(tblTasks[Task Name],tblTasks[Project ID]=$B$5),12),"") | C25: =IFERROR(INDEX(FILTER(tblTasks[Assigned User],tblTasks[Project ID]=$B$5),12),"") | D25: =IFERROR(INDEX(FILTER(tblTasks[Manual Status],tblTasks[Project ID]=$B$5),12),"") | E25: =IFERROR(INDEX(FILTER(tblTasks[Priority],tblTasks[Project ID]=$B$5),12),"") | F25: =IFERROR(INDEX(FILTER(tblTasks[Progress %],tblTasks[Project ID]=$B$5),12),"") | G25: =IFERROR(INDEX(FILTER(tblTasks[Auto Health],tblTasks[Project ID]=$B$5),12),"") | H25: =IFERROR(INDEX(FILTER(tblTasks[Due Date],tblTasks[Project ID]=$B$5),12),"")
A26: =IFERROR(INDEX(FILTER(tblTasks[Task ID],tblTasks[Project ID]=$B$5),13),"") | B26: =IFERROR(INDEX(FILTER(tblTasks[Task Name],tblTasks[Project ID]=$B$5),13),"") | C26: =IFERROR(INDEX(FILTER(tblTasks[Assigned User],tblTasks[Project ID]=$B$5),13),"") | D26: =IFERROR(INDEX(FILTER(tblTasks[Manual Status],tblTasks[Project ID]=$B$5),13),"") | E26: =IFERROR(INDEX(FILTER(tblTasks[Priority],tblTasks[Project ID]=$B$5),13),"") | F26: =IFERROR(INDEX(FILTER(tblTasks[Progress %],tblTasks[Project ID]=$B$5),13),"") | G26: =IFERROR(INDEX(FILTER(tblTasks[Auto Health],tblTasks[Project ID]=$B$5),13),"") | H26: =IFERROR(INDEX(FILTER(tblTasks[Due Date],tblTasks[Project ID]=$B$5),13),"")
A27: =IFERROR(INDEX(FILTER(tblTasks[Task ID],tblTasks[Project ID]=$B$5),14),"") | B27: =IFERROR(INDEX(FILTER(tblTasks[Task Name],tblTasks[Project ID]=$B$5),14),"") | C27: =IFERROR(INDEX(FILTER(tblTasks[Assigned User],tblTasks[Project ID]=$B$5),14),"") | D27: =IFERROR(INDEX(FILTER(tblTasks[Manual Status],tblTasks[Project ID]=$B$5),14),"") | E27: =IFERROR(INDEX(FILTER(tblTasks[Priority],tblTasks[Project ID]=$B$5),14),"") | F27: =IFERROR(INDEX(FILTER(tblTasks[Progress %],tblTasks[Project ID]=$B$5),14),"") | G27: =IFERROR(INDEX(FILTER(tblTasks[Auto Health],tblTasks[Project ID]=$B$5),14),"") | H27: =IFERROR(INDEX(FILTER(tblTasks[Due Date],tblTasks[Project ID]=$B$5),14),"")
A28: =IFERROR(INDEX(FILTER(tblTasks[Task ID],tblTasks[Project ID]=$B$5),15),"") | B28: =IFERROR(INDEX(FILTER(tblTasks[Task Name],tblTasks[Project ID]=$B$5),15),"") | C28: =IFERROR(INDEX(FILTER(tblTasks[Assigned User],tblTasks[Project ID]=$B$5),15),"") | D28: =IFERROR(INDEX(FILTER(tblTasks[Manual Status],tblTasks[Project ID]=$B$5),15),"") | E28: =IFERROR(INDEX(FILTER(tblTasks[Priority],tblTasks[Project ID]=$B$5),15),"") | F28: =IFERROR(INDEX(FILTER(tblTasks[Progress %],tblTasks[Project ID]=$B$5),15),"") | G28: =IFERROR(INDEX(FILTER(tblTasks[Auto Health],tblTasks[Project ID]=$B$5),15),"") | H28: =IFERROR(INDEX(FILTER(tblTasks[Due Date],tblTasks[Project ID]=$B$5),15),"")
A31: Recent Activity
A32: Date | B32: Type | C32: User | D32: Task | E32: Comment
A33: =IFERROR(INDEX(FILTER(tblActivity[Activity Date],tblActivity[Project ID]=$B$5),1),"") | B33: =IFERROR(INDEX(FILTER(tblActivity[Activity Type],tblActivity[Project ID]=$B$5),1),"") | C33: =IFERROR(INDEX(FILTER(tblActivity[User ID],tblActivity[Project ID]=$B$5),1),"") | D33: =IFERROR(INDEX(FILTER(tblActivity[Task ID],tblActivity[Project ID]=$B$5),1),"") | E33: =IFERROR(INDEX(FILTER(tblActivity[Comment / Update],tblActivity[Project ID]=$B$5),1),"")
A34: =IFERROR(INDEX(FILTER(tblActivity[Activity Date],tblActivity[Project ID]=$B$5),2),"") | B34: =IFERROR(INDEX(FILTER(tblActivity[Activity Type],tblActivity[Project ID]=$B$5),2),"") | C34: =IFERROR(INDEX(FILTER(tblActivity[User ID],tblActivity[Project ID]=$B$5),2),"") | D34: =IFERROR(INDEX(FILTER(tblActivity[Task ID],tblActivity[Project ID]=$B$5),2),"") | E34: =IFERROR(INDEX(FILTER(tblActivity[Comment / Update],tblActivity[Project ID]=$B$5),2),"")
A35: =IFERROR(INDEX(FILTER(tblActivity[Activity Date],tblActivity[Project ID]=$B$5),3),"") | B35: =IFERROR(INDEX(FILTER(tblActivity[Activity Type],tblActivity[Project ID]=$B$5),3),"") | C35: =IFERROR(INDEX(FILTER(tblActivity[User ID],tblActivity[Project ID]=$B$5),3),"") | D35: =IFERROR(INDEX(FILTER(tblActivity[Task ID],tblActivity[Project ID]=$B$5),3),"") | E35: =IFERROR(INDEX(FILTER(tblActivity[Comment / Update],tblActivity[Project ID]=$B$5),3),"")
A36: =IFERROR(INDEX(FILTER(tblActivity[Activity Date],tblActivity[Project ID]=$B$5),4),"") | B36: =IFERROR(INDEX(FILTER(tblActivity[Activity Type],tblActivity[Project ID]=$B$5),4),"") | C36: =IFERROR(INDEX(FILTER(tblActivity[User ID],tblActivity[Project ID]=$B$5),4),"") | D36: =IFERROR(INDEX(FILTER(tblActivity[Task ID],tblActivity[Project ID]=$B$5),4),"") | E36: =IFERROR(INDEX(FILTER(tblActivity[Comment / Update],tblActivity[Project ID]=$B$5),4),"")
A37: =IFERROR(INDEX(FILTER(tblActivity[Activity Date],tblActivity[Project ID]=$B$5),5),"") | B37: =IFERROR(INDEX(FILTER(tblActivity[Activity Type],tblActivity[Project ID]=$B$5),5),"") | C37: =IFERROR(INDEX(FILTER(tblActivity[User ID],tblActivity[Project ID]=$B$5),5),"") | D37: =IFERROR(INDEX(FILTER(tblActivity[Task ID],tblActivity[Project ID]=$B$5),5),"") | E37: =IFERROR(INDEX(FILTER(tblActivity[Comment / Update],tblActivity[Project ID]=$B$5),5),"")
A38: =IFERROR(INDEX(FILTER(tblActivity[Activity Date],tblActivity[Project ID]=$B$5),6),"") | B38: =IFERROR(INDEX(FILTER(tblActivity[Activity Type],tblActivity[Project ID]=$B$5),6),"") | C38: =IFERROR(INDEX(FILTER(tblActivity[User ID],tblActivity[Project ID]=$B$5),6),"") | D38: =IFERROR(INDEX(FILTER(tblActivity[Task ID],tblActivity[Project ID]=$B$5),6),"") | E38: =IFERROR(INDEX(FILTER(tblActivity[Comment / Update],tblActivity[Project ID]=$B$5),6),"")
A39: =IFERROR(INDEX(FILTER(tblActivity[Activity Date],tblActivity[Project ID]=$B$5),7),"") | B39: =IFERROR(INDEX(FILTER(tblActivity[Activity Type],tblActivity[Project ID]=$B$5),7),"") | C39: =IFERROR(INDEX(FILTER(tblActivity[User ID],tblActivity[Project ID]=$B$5),7),"") | D39: =IFERROR(INDEX(FILTER(tblActivity[Task ID],tblActivity[Project ID]=$B$5),7),"") | E39: =IFERROR(INDEX(FILTER(tblActivity[Comment / Update],tblActivity[Project ID]=$B$5),7),"")
A40: =IFERROR(INDEX(FILTER(tblActivity[Activity Date],tblActivity[Project ID]=$B$5),8),"") | B40: =IFERROR(INDEX(FILTER(tblActivity[Activity Type],tblActivity[Project ID]=$B$5),8),"") | C40: =IFERROR(INDEX(FILTER(tblActivity[User ID],tblActivity[Project ID]=$B$5),8),"") | D40: =IFERROR(INDEX(FILTER(tblActivity[Task ID],tblActivity[Project ID]=$B$5),8),"") | E40: =IFERROR(INDEX(FILTER(tblActivity[Comment / Update],tblActivity[Project ID]=$B$5),8),"")
A41: =IFERROR(INDEX(FILTER(tblActivity[Activity Date],tblActivity[Project ID]=$B$5),9),"") | B41: =IFERROR(INDEX(FILTER(tblActivity[Activity Type],tblActivity[Project ID]=$B$5),9),"") | C41: =IFERROR(INDEX(FILTER(tblActivity[User ID],tblActivity[Project ID]=$B$5),9),"") | D41: =IFERROR(INDEX(FILTER(tblActivity[Task ID],tblActivity[Project ID]=$B$5),9),"") | E41: =IFERROR(INDEX(FILTER(tblActivity[Comment / Update],tblActivity[Project ID]=$B$5),9),"")

Sheet Projects
A1: Projects
A2: Multi-project portfolio master
A3: Home | B3: Dashboard | C3: Workspace | D3: Projects | E3: Tasks | F3: Issues | G3: Timesheets | H3: Reports | I3: Master
A5: Project ID | B5: Project Name | C5: Client ID | D5: Team ID | E5: Project Manager | F5: Start Date | G5: End Date | H5: Manual Status | I5: Priority | J5: Budget | K5: Actual Cost | L5: Task Count | M5: Completed Tasks | N5: Open Issues | O5: Open Risks | P5: Logged Hours | Q5: Progress % | R5: Auto Health | S5: Days Remaining | T5: Project Group | U5: Notes
A6: PRJ-001 | B6: ERP Modernization | C6: CL-001 | D6: TEAM-001 | E6: USR-001 | F6: 46142 | G6: 46232 | H6: In Progress | I6: Critical | J6: 750000 | K6: 280000 | L6: =COUNTIF(tblTasks[Project ID],[@[Project ID]]) | M6: =COUNTIFS(tblTasks[Project ID],[@[Project ID]],tblTasks[Manual Status],"Completed") | N6: =COUNTIFS(tblIssues[Project ID],[@[Project ID]],tblIssues[Status],"<>Closed",tblIssues[Status],"<>Resolved") | O6: =COUNTIFS(tblRisks[Project ID],[@[Project ID]],tblRisks[Status],"<>Closed") | P6: =SUMIF(tblTimesheets[Project ID],[@[Project ID]],tblTimesheets[Hours]) | Q6: =IFERROR([@[Completed Tasks]]/[@[Task Count]],0) | R6: =IF([@[Manual Status]]="Completed","Completed",IF(COUNTIFS(tblTasks[Project ID],[@[Project ID]],tblTasks[Auto Health],"Overdue")>0,"Overdue",IF(COUNTIFS(tblTasks[Project ID],[@[Project ID]],tblTasks[Auto Health],"At Risk")>0,"At Risk",IF(COUNTIFS(tblTasks[Project ID],[@[Project ID]],tblTasks[Manual Status],"Blocked")>0,"Blocked",IF([@[Task Count]]=0,"Not Started","On Track"))))) | S6: =MAX(0,[@[End Date]]-TODAY()) | T6: Strategic | U6: Core ERP transformation
A7: PRJ-002 | B7: Customer Portal | C7: CL-002 | D7: TEAM-001 | E7: USR-001 | F7: 46162 | G7: 46217 | H7: In Progress | I7: High | J7: 320000 | K7: 85000 | L7: =COUNTIF(tblTasks[Project ID],[@[Project ID]]) | M7: =COUNTIFS(tblTasks[Project ID],[@[Project ID]],tblTasks[Manual Status],"Completed") | N7: =COUNTIFS(tblIssues[Project ID],[@[Project ID]],tblIssues[Status],"<>Closed",tblIssues[Status],"<>Resolved") | O7: =COUNTIFS(tblRisks[Project ID],[@[Project ID]],tblRisks[Status],"<>Closed") | P7: =SUMIF(tblTimesheets[Project ID],[@[Project ID]],tblTimesheets[Hours]) | Q7: =IFERROR([@[Completed Tasks]]/[@[Task Count]],0) | R7: =IF([@[Manual Status]]="Completed","Completed",IF(COUNTIFS(tblTasks[Project ID],[@[Project ID]],tblTasks[Auto Health],"Overdue")>0,"Overdue",IF(COUNTIFS(tblTasks[Project ID],[@[Project ID]],tblTasks[Auto Health],"At Risk")>0,"At Risk",IF(COUNTIFS(tblTasks[Project ID],[@[Project ID]],tblTasks[Manual Status],"Blocked")>0,"Blocked",IF([@[Task Count]]=0,"Not Started","On Track"))))) | S7: =MAX(0,[@[End Date]]-TODAY()) | T7: Customer Experience | U7: Self-service portal
A8: PRJ-003 | B8: Data Quality Program | C8: CL-003 | D8: TEAM-002 | E8: USR-004 | F8: 46117 | G8: 46202 | H8: Planning | I8: Medium | J8: 150000 | K8: 45000 | L8: =COUNTIF(tblTasks[Project ID],[@[Project ID]]) | M8: =COUNTIFS(tblTasks[Project ID],[@[Project ID]],tblTasks[Manual Status],"Completed") | N8: =COUNTIFS(tblIssues[Project ID],[@[Project ID]],tblIssues[Status],"<>Closed",tblIssues[Status],"<>Resolved") | O8: =COUNTIFS(tblRisks[Project ID],[@[Project ID]],tblRisks[Status],"<>Closed") | P8: =SUMIF(tblTimesheets[Project ID],[@[Project ID]],tblTimesheets[Hours]) | Q8: =IFERROR([@[Completed Tasks]]/[@[Task Count]],0) | R8: =IF([@[Manual Status]]="Completed","Completed",IF(COUNTIFS(tblTasks[Project ID],[@[Project ID]],tblTasks[Auto Health],"Overdue")>0,"Overdue",IF(COUNTIFS(tblTasks[Project ID],[@[Project ID]],tblTasks[Auto Health],"At Risk")>0,"At Risk",IF(COUNTIFS(tblTasks[Project ID],[@[Project ID]],tblTasks[Manual Status],"Blocked")>0,"Blocked",IF([@[Task Count]]=0,"Not Started","On Track"))))) | S8: =MAX(0,[@[End Date]]-TODAY()) | T8: Governance | U8: Data quality remediation
A9: PRJ-004 | B9: Branch Ops Automation | C9: CL-004 | D9: TEAM-003 | E9: USR-005 | F9: 46172 | G9: 46252 | H9: Not Started | I9: High | J9: 410000 | K9: 20000 | L9: =COUNTIF(tblTasks[Project ID],[@[Project ID]]) | M9: =COUNTIFS(tblTasks[Project ID],[@[Project ID]],tblTasks[Manual Status],"Completed") | N9: =COUNTIFS(tblIssues[Project ID],[@[Project ID]],tblIssues[Status],"<>Closed",tblIssues[Status],"<>Resolved") | O9: =COUNTIFS(tblRisks[Project ID],[@[Project ID]],tblRisks[Status],"<>Closed") | P9: =SUMIF(tblTimesheets[Project ID],[@[Project ID]],tblTimesheets[Hours]) | Q9: =IFERROR([@[Completed Tasks]]/[@[Task Count]],0) | R9: =IF([@[Manual Status]]="Completed","Completed",IF(COUNTIFS(tblTasks[Project ID],[@[Project ID]],tblTasks[Auto Health],"Overdue")>0,"Overdue",IF(COUNTIFS(tblTasks[Project ID],[@[Project ID]],tblTasks[Auto Health],"At Risk")>0,"At Risk",IF(COUNTIFS(tblTasks[Project ID],[@[Project ID]],tblTasks[Manual Status],"Blocked")>0,"Blocked",IF([@[Task Count]]=0,"Not Started","On Track"))))) | S9: =MAX(0,[@[End Date]]-TODAY()) | T9: Automation | U9: Workflow automation
A10: PRJ-005 | B10: Mobile App Refresh | C10: CL-002 | D10: TEAM-001 | E10: USR-003 | F10: 46092 | G10: 46177 | H10: Completed | I10: Medium | J10: 180000 | K10: 175000 | L10: =COUNTIF(tblTasks[Project ID],[@[Project ID]]) | M10: =COUNTIFS(tblTasks[Project ID],[@[Project ID]],tblTasks[Manual Status],"Completed") | N10: =COUNTIFS(tblIssues[Project ID],[@[Project ID]],tblIssues[Status],"<>Closed",tblIssues[Status],"<>Resolved") | O10: =COUNTIFS(tblRisks[Project ID],[@[Project ID]],tblRisks[Status],"<>Closed") | P10: =SUMIF(tblTimesheets[Project ID],[@[Project ID]],tblTimesheets[Hours]) | Q10: =IFERROR([@[Completed Tasks]]/[@[Task Count]],0) | R10: =IF([@[Manual Status]]="Completed","Completed",IF(COUNTIFS(tblTasks[Project ID],[@[Project ID]],tblTasks[Auto Health],"Overdue")>0,"Overdue",IF(COUNTIFS(tblTasks[Project ID],[@[Project ID]],tblTasks[Auto Health],"At Risk")>0,"At Risk",IF(COUNTIFS(tblTasks[Project ID],[@[Project ID]],tblTasks[Manual Status],"Blocked")>0,"Blocked",IF([@[Task Count]]=0,"Not Started","On Track"))))) | S10: =MAX(0,[@[End Date]]-TODAY()) | T10: Experience | U10: Mobile UX refresh

Sheet Tasks
A1: Tasks
A2: Project-aware task list with dependencies and health
A3: Home | B3: Dashboard | C3: Workspace | D3: Projects | E3: Tasks | F3: Issues | G3: Timesheets | H3: Reports | I3: Master
A5: Task ID | B5: Project ID | C5: Task Name | D5: Category | E5: Assigned User | F5: Start Date | G5: Due Date | H5: Manual Status | I5: Priority | J5: Progress % | K5: Depends On Task ID | L5: Blocked? | M5: Blocking Reason | N5: Sprint / Phase | O5: Subtask Count | P5: Completed Subtasks | Q5: Issue Count | R5: Logged Hours | S5: Auto Health | T5: Days Late | U5: Notes
A6: TSK-001 | B6: PRJ-001 | C6: Requirements workshop | D6: Requirement | E6: USR-001 | F6: 46147 | G6: 46162 | H6: Completed | I6: High | J6: 1 | L6: No | N6: Sprint 1 | O6: =COUNTIF(tblSubtasks[Parent Task ID],[@[Task ID]]) | P6: =COUNTIFS(tblSubtasks[Parent Task ID],[@[Task ID]],tblSubtasks[Manual Status],"Completed") | Q6: =COUNTIFS(tblIssues[Task ID],[@[Task ID]],tblIssues[Status],"<>Closed",tblIssues[Status],"<>Resolved") | R6: =SUMIF(tblTimesheets[Task ID],[@[Task ID]],tblTimesheets[Hours]) | S6: =IF([@[Manual Status]]="Completed","Completed",IF([@[Manual Status]]="Blocked","Blocked",IF(AND([@[Due Date]]<TODAY(),[@[Manual Status]]<>"Completed",[@[Manual Status]]<>"Cancelled"),"Overdue",IF(AND([@[Due Date]]-TODAY()<=3,[@[Progress %]]<0.8),"At Risk",IF([@[Progress %]]=0,"Not Started","On Track"))))) | T6: =IF(AND([@[Due Date]]<TODAY(),[@[Manual Status]]<>"Completed"),TODAY()-[@[Due Date]],0)
A7: TSK-002 | B7: PRJ-001 | C7: Integration design | D7: Design | E7: USR-003 | F7: 46164 | G7: 46187 | H7: In Progress | I7: Critical | J7: 0.65 | K7: TSK-001 | L7: No | N7: Sprint 2 | O7: =COUNTIF(tblSubtasks[Parent Task ID],[@[Task ID]]) | P7: =COUNTIFS(tblSubtasks[Parent Task ID],[@[Task ID]],tblSubtasks[Manual Status],"Completed") | Q7: =COUNTIFS(tblIssues[Task ID],[@[Task ID]],tblIssues[Status],"<>Closed",tblIssues[Status],"<>Resolved") | R7: =SUMIF(tblTimesheets[Task ID],[@[Task ID]],tblTimesheets[Hours]) | S7: =IF([@[Manual Status]]="Completed","Completed",IF([@[Manual Status]]="Blocked","Blocked",IF(AND([@[Due Date]]<TODAY(),[@[Manual Status]]<>"Completed",[@[Manual Status]]<>"Cancelled"),"Overdue",IF(AND([@[Due Date]]-TODAY()<=3,[@[Progress %]]<0.8),"At Risk",IF([@[Progress %]]=0,"Not Started","On Track"))))) | T7: =IF(AND([@[Due Date]]<TODAY(),[@[Manual Status]]<>"Completed"),TODAY()-[@[Due Date]],0)
A8: TSK-003 | B8: PRJ-001 | C8: Build Oracle connector | D8: Development | E8: USR-002 | F8: 46176 | G8: 46200 | H8: In Progress | I8: Critical | J8: 0.32 | K8: TSK-002 | L8: No | N8: Sprint 2 | O8: =COUNTIF(tblSubtasks[Parent Task ID],[@[Task ID]]) | P8: =COUNTIFS(tblSubtasks[Parent Task ID],[@[Task ID]],tblSubtasks[Manual Status],"Completed") | Q8: =COUNTIFS(tblIssues[Task ID],[@[Task ID]],tblIssues[Status],"<>Closed",tblIssues[Status],"<>Resolved") | R8: =SUMIF(tblTimesheets[Task ID],[@[Task ID]],tblTimesheets[Hours]) | S8: =IF([@[Manual Status]]="Completed","Completed",IF([@[Manual Status]]="Blocked","Blocked",IF(AND([@[Due Date]]<TODAY(),[@[Manual Status]]<>"Completed",[@[Manual Status]]<>"Cancelled"),"Overdue",IF(AND([@[Due Date]]-TODAY()<=3,[@[Progress %]]<0.8),"At Risk",IF([@[Progress %]]=0,"Not Started","On Track"))))) | T8: =IF(AND([@[Due Date]]<TODAY(),[@[Manual Status]]<>"Completed"),TODAY()-[@[Due Date]],0)
A9: TSK-004 | B9: PRJ-002 | C9: Portal wireframes | D9: Design | E9: USR-003 | F9: 46167 | G9: 46180 | H9: Completed | I9: High | J9: 1 | L9: No | N9: Sprint 1 | O9: =COUNTIF(tblSubtasks[Parent Task ID],[@[Task ID]]) | P9: =COUNTIFS(tblSubtasks[Parent Task ID],[@[Task ID]],tblSubtasks[Manual Status],"Completed") | Q9: =COUNTIFS(tblIssues[Task ID],[@[Task ID]],tblIssues[Status],"<>Closed",tblIssues[Status],"<>Resolved") | R9: =SUMIF(tblTimesheets[Task ID],[@[Task ID]],tblTimesheets[Hours]) | S9: =IF([@[Manual Status]]="Completed","Completed",IF([@[Manual Status]]="Blocked","Blocked",IF(AND([@[Due Date]]<TODAY(),[@[Manual Status]]<>"Completed",[@[Manual Status]]<>"Cancelled"),"Overdue",IF(AND([@[Due Date]]-TODAY()<=3,[@[Progress %]]<0.8),"At Risk",IF([@[Progress %]]=0,"Not Started","On Track"))))) | T9: =IF(AND([@[Due Date]]<TODAY(),[@[Manual Status]]<>"Completed"),TODAY()-[@[Due Date]],0)
A10: TSK-005 | B10: PRJ-002 | C10: Authentication module | D10: Development | E10: USR-002 | F10: 46174 | G10: 46204 | H10: Blocked | I10: High | J10: 0.2 | K10: TSK-004 | L10: Yes | M10: Security review pending | N10: Sprint 2 | O10: =COUNTIF(tblSubtasks[Parent Task ID],[@[Task ID]]) | P10: =COUNTIFS(tblSubtasks[Parent Task ID],[@[Task ID]],tblSubtasks[Manual Status],"Completed") | Q10: =COUNTIFS(tblIssues[Task ID],[@[Task ID]],tblIssues[Status],"<>Closed",tblIssues[Status],"<>Resolved") | R10: =SUMIF(tblTimesheets[Task ID],[@[Task ID]],tblTimesheets[Hours]) | S10: =IF([@[Manual Status]]="Completed","Completed",IF([@[Manual Status]]="Blocked","Blocked",IF(AND([@[Due Date]]<TODAY(),[@[Manual Status]]<>"Completed",[@[Manual Status]]<>"Cancelled"),"Overdue",IF(AND([@[Due Date]]-TODAY()<=3,[@[Progress %]]<0.8),"At Risk",IF([@[Progress %]]=0,"Not Started","On Track"))))) | T10: =IF(AND([@[Due Date]]<TODAY(),[@[Manual Status]]<>"Completed"),TODAY()-[@[Due Date]],0)
A11: TSK-006 | B11: PRJ-003 | C11: Data profiling | D11: Research | E11: USR-004 | F11: 46127 | G11: 46174 | H11: In Progress | I11: Medium | J11: 0.7 | L11: No | N11: Phase 1 | O11: =COUNTIF(tblSubtasks[Parent Task ID],[@[Task ID]]) | P11: =COUNTIFS(tblSubtasks[Parent Task ID],[@[Task ID]],tblSubtasks[Manual Status],"Completed") | Q11: =COUNTIFS(tblIssues[Task ID],[@[Task ID]],tblIssues[Status],"<>Closed",tblIssues[Status],"<>Resolved") | R11: =SUMIF(tblTimesheets[Task ID],[@[Task ID]],tblTimesheets[Hours]) | S11: =IF([@[Manual Status]]="Completed","Completed",IF([@[Manual Status]]="Blocked","Blocked",IF(AND([@[Due Date]]<TODAY(),[@[Manual Status]]<>"Completed",[@[Manual Status]]<>"Cancelled"),"Overdue",IF(AND([@[Due Date]]-TODAY()<=3,[@[Progress %]]<0.8),"At Risk",IF([@[Progress %]]=0,"Not Started","On Track"))))) | T11: =IF(AND([@[Due Date]]<TODAY(),[@[Manual Status]]<>"Completed"),TODAY()-[@[Due Date]],0)
A12: TSK-007 | B12: PRJ-003 | C12: Remediation plan | D12: Documentation | E12: USR-006 | F12: 46177 | G12: 46192 | H12: Not Started | I12: Medium | J12: 0 | K12: TSK-006 | L12: No | N12: Phase 1 | O12: =COUNTIF(tblSubtasks[Parent Task ID],[@[Task ID]]) | P12: =COUNTIFS(tblSubtasks[Parent Task ID],[@[Task ID]],tblSubtasks[Manual Status],"Completed") | Q12: =COUNTIFS(tblIssues[Task ID],[@[Task ID]],tblIssues[Status],"<>Closed",tblIssues[Status],"<>Resolved") | R12: =SUMIF(tblTimesheets[Task ID],[@[Task ID]],tblTimesheets[Hours]) | S12: =IF([@[Manual Status]]="Completed","Completed",IF([@[Manual Status]]="Blocked","Blocked",IF(AND([@[Due Date]]<TODAY(),[@[Manual Status]]<>"Completed",[@[Manual Status]]<>"Cancelled"),"Overdue",IF(AND([@[Due Date]]-TODAY()<=3,[@[Progress %]]<0.8),"At Risk",IF([@[Progress %]]=0,"Not Started","On Track"))))) | T12: =IF(AND([@[Due Date]]<TODAY(),[@[Manual Status]]<>"Completed"),TODAY()-[@[Due Date]],0)
A13: TSK-008 | B13: PRJ-004 | C13: Workflow mapping | D13: Requirement | E13: USR-006 | F13: 46178 | G13: 46194 | H13: In Progress | I13: High | J13: 0.35 | L13: No | N13: Discovery | O13: =COUNTIF(tblSubtasks[Parent Task ID],[@[Task ID]]) | P13: =COUNTIFS(tblSubtasks[Parent Task ID],[@[Task ID]],tblSubtasks[Manual Status],"Completed") | Q13: =COUNTIFS(tblIssues[Task ID],[@[Task ID]],tblIssues[Status],"<>Closed",tblIssues[Status],"<>Resolved") | R13: =SUMIF(tblTimesheets[Task ID],[@[Task ID]],tblTimesheets[Hours]) | S13: =IF([@[Manual Status]]="Completed","Completed",IF([@[Manual Status]]="Blocked","Blocked",IF(AND([@[Due Date]]<TODAY(),[@[Manual Status]]<>"Completed",[@[Manual Status]]<>"Cancelled"),"Overdue",IF(AND([@[Due Date]]-TODAY()<=3,[@[Progress %]]<0.8),"At Risk",IF([@[Progress %]]=0,"Not Started","On Track"))))) | T13: =IF(AND([@[Due Date]]<TODAY(),[@[Manual Status]]<>"Completed"),TODAY()-[@[Due Date]],0)
A14: TSK-009 | B14: PRJ-004 | C14: Pilot deployment | D14: Deployment | E14: USR-005 | F14: 46192 | G14: 46227 | H14: Not Started | I14: High | J14: 0 | K14: TSK-008 | L14: No | N14: Pilot | O14: =COUNTIF(tblSubtasks[Parent Task ID],[@[Task ID]]) | P14: =COUNTIFS(tblSubtasks[Parent Task ID],[@[Task ID]],tblSubtasks[Manual Status],"Completed") | Q14: =COUNTIFS(tblIssues[Task ID],[@[Task ID]],tblIssues[Status],"<>Closed",tblIssues[Status],"<>Resolved") | R14: =SUMIF(tblTimesheets[Task ID],[@[Task ID]],tblTimesheets[Hours]) | S14: =IF([@[Manual Status]]="Completed","Completed",IF([@[Manual Status]]="Blocked","Blocked",IF(AND([@[Due Date]]<TODAY(),[@[Manual Status]]<>"Completed",[@[Manual Status]]<>"Cancelled"),"Overdue",IF(AND([@[Due Date]]-TODAY()<=3,[@[Progress %]]<0.8),"At Risk",IF([@[Progress %]]=0,"Not Started","On Track"))))) | T14: =IF(AND([@[Due Date]]<TODAY(),[@[Manual Status]]<>"Completed"),TODAY()-[@[Due Date]],0)
A15: TSK-010 | B15: PRJ-005 | C15: Release closure | D15: Deployment | E15: USR-005 | F15: 46162 | G15: 46177 | H15: Completed | I15: Medium | J15: 1 | L15: No | N15: Closure | O15: =COUNTIF(tblSubtasks[Parent Task ID],[@[Task ID]]) | P15: =COUNTIFS(tblSubtasks[Parent Task ID],[@[Task ID]],tblSubtasks[Manual Status],"Completed") | Q15: =COUNTIFS(tblIssues[Task ID],[@[Task ID]],tblIssues[Status],"<>Closed",tblIssues[Status],"<>Resolved") | R15: =SUMIF(tblTimesheets[Task ID],[@[Task ID]],tblTimesheets[Hours]) | S15: =IF([@[Manual Status]]="Completed","Completed",IF([@[Manual Status]]="Blocked","Blocked",IF(AND([@[Due Date]]<TODAY(),[@[Manual Status]]<>"Completed",[@[Manual Status]]<>"Cancelled"),"Overdue",IF(AND([@[Due Date]]-TODAY()<=3,[@[Progress %]]<0.8),"At Risk",IF([@[Progress %]]=0,"Not Started","On Track"))))) | T15: =IF(AND([@[Due Date]]<TODAY(),[@[Manual Status]]<>"Completed"),TODAY()-[@[Due Date]],0)

Sheet Subtasks
A1: Subtasks
A2: Detailed execution checklist
A3: Home | B3: Dashboard | C3: Workspace | D3: Projects | E3: Tasks | F3: Issues | G3: Timesheets | H3: Reports | I3: Master
A5: Subtask ID | B5: Parent Task ID | C5: Project ID | D5: Subtask Name | E5: Assigned User | F5: Due Date | G5: Manual Status | H5: Priority | I5: Completion % | J5: Auto Health | K5: Days Late
A6: SUB-001 | B6: TSK-002 | C6: PRJ-001 | D6: Interface inventory | E6: USR-003 | F6: 46184 | G6: In Progress | H6: High | I6: 0.7 | J6: =IF([@[Manual Status]]="Completed","Completed",IF(AND([@[Due Date]]<TODAY(),[@[Manual Status]]<>"Completed"),"Overdue",IF(AND([@[Due Date]]-TODAY()<=3,[@[Completion %]]<0.8),"At Risk",IF([@[Completion %]]=0,"Not Started","On Track")))) | K6: =IF(AND([@[Due Date]]<TODAY(),[@[Manual Status]]<>"Completed"),TODAY()-[@[Due Date]],0)
A7: SUB-002 | B7: TSK-003 | C7: PRJ-001 | D7: Connection pool | E7: USR-002 | F7: 46190 | G7: Not Started | H7: Critical | I7: 0 | J7: =IF([@[Manual Status]]="Completed","Completed",IF(AND([@[Due Date]]<TODAY(),[@[Manual Status]]<>"Completed"),"Overdue",IF(AND([@[Due Date]]-TODAY()<=3,[@[Completion %]]<0.8),"At Risk",IF([@[Completion %]]=0,"Not Started","On Track")))) | K7: =IF(AND([@[Due Date]]<TODAY(),[@[Manual Status]]<>"Completed"),TODAY()-[@[Due Date]],0)
A8: SUB-003 | B8: TSK-005 | C8: PRJ-002 | D8: SSO spike | E8: USR-002 | F8: 46188 | G8: Blocked | H8: High | I8: 0.15 | J8: =IF([@[Manual Status]]="Completed","Completed",IF(AND([@[Due Date]]<TODAY(),[@[Manual Status]]<>"Completed"),"Overdue",IF(AND([@[Due Date]]-TODAY()<=3,[@[Completion %]]<0.8),"At Risk",IF([@[Completion %]]=0,"Not Started","On Track")))) | K8: =IF(AND([@[Due Date]]<TODAY(),[@[Manual Status]]<>"Completed"),TODAY()-[@[Due Date]],0)
A9: SUB-004 | B9: TSK-006 | C9: PRJ-003 | D9: Profile customer table | E9: USR-004 | F9: 46178 | G9: In Progress | H9: Medium | I9: 0.8 | J9: =IF([@[Manual Status]]="Completed","Completed",IF(AND([@[Due Date]]<TODAY(),[@[Manual Status]]<>"Completed"),"Overdue",IF(AND([@[Due Date]]-TODAY()<=3,[@[Completion %]]<0.8),"At Risk",IF([@[Completion %]]=0,"Not Started","On Track")))) | K9: =IF(AND([@[Due Date]]<TODAY(),[@[Manual Status]]<>"Completed"),TODAY()-[@[Due Date]],0)
A10: SUB-005 | B10: TSK-008 | C10: PRJ-004 | D10: Current-state process map | E10: USR-006 | F10: 46187 | G10: In Progress | H10: High | I10: 0.45 | J10: =IF([@[Manual Status]]="Completed","Completed",IF(AND([@[Due Date]]<TODAY(),[@[Manual Status]]<>"Completed"),"Overdue",IF(AND([@[Due Date]]-TODAY()<=3,[@[Completion %]]<0.8),"At Risk",IF([@[Completion %]]=0,"Not Started","On Track")))) | K10: =IF(AND([@[Due Date]]<TODAY(),[@[Manual Status]]<>"Completed"),TODAY()-[@[Due Date]],0)

Sheet Milestones
A1: Milestones
A2: Major checkpoints and delivery gates
A3: Home | B3: Dashboard | C3: Workspace | D3: Projects | E3: Tasks | F3: Issues | G3: Timesheets | H3: Reports | I3: Master
A5: Milestone ID | B5: Project ID | C5: Milestone Name | D5: Owner | E5: Target Date | F5: Manual Status | G5: Priority | H5: Auto Health | I5: Days Remaining
A6: MS-001 | B6: PRJ-001 | C6: Architecture sign-off | D6: USR-001 | E6: 46194 | F6: In Progress | G6: Critical | H6: =IF([@[Manual Status]]="Completed","Completed",IF(AND([@[Target Date]]<TODAY(),[@[Manual Status]]<>"Completed"),"Overdue",IF([@[Target Date]]-TODAY()<=5,"At Risk","On Track"))) | I6: =MAX(0,[@[Target Date]]-TODAY())
A7: MS-002 | B7: PRJ-002 | C7: Portal beta | D7: USR-001 | E7: 46207 | F7: Not Started | G7: High | H7: =IF([@[Manual Status]]="Completed","Completed",IF(AND([@[Target Date]]<TODAY(),[@[Manual Status]]<>"Completed"),"Overdue",IF([@[Target Date]]-TODAY()<=5,"At Risk","On Track"))) | I7: =MAX(0,[@[Target Date]]-TODAY())
A8: MS-003 | B8: PRJ-003 | C8: DQ baseline approved | D8: USR-004 | E8: 46186 | F8: In Progress | G8: Medium | H8: =IF([@[Manual Status]]="Completed","Completed",IF(AND([@[Target Date]]<TODAY(),[@[Manual Status]]<>"Completed"),"Overdue",IF([@[Target Date]]-TODAY()<=5,"At Risk","On Track"))) | I8: =MAX(0,[@[Target Date]]-TODAY())
A9: MS-004 | B9: PRJ-004 | C9: Pilot go-live | D9: USR-005 | E9: 46232 | F9: Not Started | G9: High | H9: =IF([@[Manual Status]]="Completed","Completed",IF(AND([@[Target Date]]<TODAY(),[@[Manual Status]]<>"Completed"),"Overdue",IF([@[Target Date]]-TODAY()<=5,"At Risk","On Track"))) | I9: =MAX(0,[@[Target Date]]-TODAY())
A10: MS-005 | B10: PRJ-005 | C10: Closure accepted | D10: USR-001 | E10: 46179 | F10: Completed | G10: Medium | H10: =IF([@[Manual Status]]="Completed","Completed",IF(AND([@[Target Date]]<TODAY(),[@[Manual Status]]<>"Completed"),"Overdue",IF([@[Target Date]]-TODAY()<=5,"At Risk","On Track"))) | I10: =MAX(0,[@[Target Date]]-TODAY())

Sheet Issues
A1: Issues
A2: Zoho-style issue and blocker register
A3: Home | B3: Dashboard | C3: Workspace | D3: Projects | E3: Tasks | F3: Issues | G3: Timesheets | H3: Reports | I3: Master
A5: Issue ID | B5: Project ID | C5: Task ID | D5: Type | E5: Title | F5: Owner | G5: Priority | H5: Status | I5: Created Date | J5: Due Date | K5: Age Days | L5: Auto Health | M5: Notes
A6: ISS-001 | B6: PRJ-001 | C6: TSK-003 | D6: Dependency | E6: Oracle access delay | F6: USR-002 | G6: High | H6: In Progress | I6: 46180 | J6: 46185 | K6: =TODAY()-[@[Created Date]] | L6: =IF([@[Status]]="Closed","Completed",IF([@[Status]]="Resolved","Completed",IF(AND([@[Due Date]]<TODAY(),[@[Status]]<>"Closed",[@[Status]]<>"Resolved"),"Overdue",IF([@[Priority]]="Critical","At Risk","On Track")))) | M6: Need DBA approval
A7: ISS-002 | B7: PRJ-002 | C7: TSK-005 | D7: Blocker | E7: Security sign-off pending | F7: USR-001 | G7: Critical | H7: Open | I7: 46177 | J7: 46183 | K7: =TODAY()-[@[Created Date]] | L7: =IF([@[Status]]="Closed","Completed",IF([@[Status]]="Resolved","Completed",IF(AND([@[Due Date]]<TODAY(),[@[Status]]<>"Closed",[@[Status]]<>"Resolved"),"Overdue",IF([@[Priority]]="Critical","At Risk","On Track")))) | M7: Escalated to security
A8: ISS-003 | B8: PRJ-003 | C8: TSK-006 | D8: Bug | E8: Missing source ownership | F8: USR-004 | G8: Medium | H8: Waiting | I8: 46172 | J8: 46188 | K8: =TODAY()-[@[Created Date]] | L8: =IF([@[Status]]="Closed","Completed",IF([@[Status]]="Resolved","Completed",IF(AND([@[Due Date]]<TODAY(),[@[Status]]<>"Closed",[@[Status]]<>"Resolved"),"Overdue",IF([@[Priority]]="Critical","At Risk","On Track")))) | M8: Waiting data steward
A9: ISS-004 | B9: PRJ-004 | C9: TSK-008 | D9: Change Request | E9: Add approval workflow | F9: USR-006 | G9: Medium | H9: Open | I9: 46181 | J9: 46196 | K9: =TODAY()-[@[Created Date]] | L9: =IF([@[Status]]="Closed","Completed",IF([@[Status]]="Resolved","Completed",IF(AND([@[Due Date]]<TODAY(),[@[Status]]<>"Closed",[@[Status]]<>"Resolved"),"Overdue",IF([@[Priority]]="Critical","At Risk","On Track")))) | M9: Scope review

Sheet Risks
A1: Risks
A2: Risk register with mitigation tracking
A3: Home | B3: Dashboard | C3: Workspace | D3: Projects | E3: Tasks | F3: Issues | G3: Timesheets | H3: Reports | I3: Master
A5: Risk ID | B5: Project ID | C5: Risk Title | D5: Owner | E5: Probability | F5: Impact | G5: Severity | H5: Mitigation | I5: Status | J5: Risk Score
A6: RSK-001 | B6: PRJ-001 | C6: Legacy schema unknowns | D6: USR-002 | E6: High | F6: Medium | G6: High | H6: Run profiling spike | I6: Mitigating | J6: =IF([@[Severity]]="Critical",9,IF([@[Severity]]="High",6,IF([@[Severity]]="Medium",3,1)))
A7: RSK-002 | B7: PRJ-002 | C7: Security approval may slip | D7: USR-001 | E7: High | F7: High | G7: Critical | H7: Escalate weekly | I7: Escalated | J7: =IF([@[Severity]]="Critical",9,IF([@[Severity]]="High",6,IF([@[Severity]]="Medium",3,1)))
A8: RSK-003 | B8: PRJ-003 | C8: Low business owner availability | D8: USR-004 | E8: Medium | F8: High | G8: Medium | H8: Set governance cadence | I8: Open | J8: =IF([@[Severity]]="Critical",9,IF([@[Severity]]="High",6,IF([@[Severity]]="Medium",3,1)))
A9: RSK-004 | B9: PRJ-004 | C9: Pilot adoption risk | D9: USR-005 | E9: Medium | F9: Medium | G9: Medium | H9: Training and hypercare | I9: Open | J9: =IF([@[Severity]]="Critical",9,IF([@[Severity]]="High",6,IF([@[Severity]]="Medium",3,1)))

Sheet Timesheets
A1: Timesheets
A2: Project and task time tracking
A3: Home | B3: Dashboard | C3: Workspace | D3: Projects | E3: Tasks | F3: Issues | G3: Timesheets | H3: Reports | I3: Master
A5: Entry ID | B5: Project ID | C5: Task ID | D5: User ID | E5: Work Date | F5: Hours | G5: Billable | H5: Work Description
A6: TIME-001 | B6: PRJ-001 | C6: TSK-002 | D6: USR-003 | E6: 46181 | F6: 6 | G6: Billable | H6: Design review
A7: TIME-002 | B7: PRJ-001 | C7: TSK-003 | D7: USR-002 | E7: 46181 | F7: 7 | G7: Billable | H7: Connector build
A8: TIME-003 | B8: PRJ-002 | C8: TSK-005 | D8: USR-002 | E8: 46180 | F8: 5 | G8: Billable | H8: Auth spike
A9: TIME-004 | B9: PRJ-003 | C9: TSK-006 | D9: USR-004 | E9: 46179 | F9: 4 | G9: Non-Billable | H9: Data profiling
A10: TIME-005 | B10: PRJ-004 | C10: TSK-008 | D10: USR-006 | E10: 46182 | F10: 6 | G10: Billable | H10: Workshop notes

Sheet Calendar
A1: Calendar
A2: Upcoming due dates across all projects
A3: Home | B3: Dashboard | C3: Workspace | D3: Projects | E3: Tasks | F3: Issues | G3: Timesheets | H3: Reports | I3: Master
A5: Item Type | B5: Project ID | C5: Item ID | D5: Title | E5: Owner | F5: Due Date | G5: Status | H5: Health
A6: Task | B6: =IFERROR(INDEX(tblTasks[Project ID],1),"") | C6: =IFERROR(INDEX(tblTasks[Task ID],1),"") | D6: =IFERROR(INDEX(tblTasks[Task Name],1),"") | E6: =IFERROR(INDEX(tblTasks[Assigned User],1),"") | F6: =IFERROR(INDEX(tblTasks[Due Date],1),"") | G6: =IFERROR(INDEX(tblTasks[Manual Status],1),"") | H6: =IFERROR(INDEX(tblTasks[Auto Health],1),"")
A7: Task | B7: =IFERROR(INDEX(tblTasks[Project ID],2),"") | C7: =IFERROR(INDEX(tblTasks[Task ID],2),"") | D7: =IFERROR(INDEX(tblTasks[Task Name],2),"") | E7: =IFERROR(INDEX(tblTasks[Assigned User],2),"") | F7: =IFERROR(INDEX(tblTasks[Due Date],2),"") | G7: =IFERROR(INDEX(tblTasks[Manual Status],2),"") | H7: =IFERROR(INDEX(tblTasks[Auto Health],2),"")
A8: Task | B8: =IFERROR(INDEX(tblTasks[Project ID],3),"") | C8: =IFERROR(INDEX(tblTasks[Task ID],3),"") | D8: =IFERROR(INDEX(tblTasks[Task Name],3),"") | E8: =IFERROR(INDEX(tblTasks[Assigned User],3),"") | F8: =IFERROR(INDEX(tblTasks[Due Date],3),"") | G8: =IFERROR(INDEX(tblTasks[Manual Status],3),"") | H8: =IFERROR(INDEX(tblTasks[Auto Health],3),"")
A9: Task | B9: =IFERROR(INDEX(tblTasks[Project ID],4),"") | C9: =IFERROR(INDEX(tblTasks[Task ID],4),"") | D9: =IFERROR(INDEX(tblTasks[Task Name],4),"") | E9: =IFERROR(INDEX(tblTasks[Assigned User],4),"") | F9: =IFERROR(INDEX(tblTasks[Due Date],4),"") | G9: =IFERROR(INDEX(tblTasks[Manual Status],4),"") | H9: =IFERROR(INDEX(tblTasks[Auto Health],4),"")
A10: Task | B10: =IFERROR(INDEX(tblTasks[Project ID],5),"") | C10: =IFERROR(INDEX(tblTasks[Task ID],5),"") | D10: =IFERROR(INDEX(tblTasks[Task Name],5),"") | E10: =IFERROR(INDEX(tblTasks[Assigned User],5),"") | F10: =IFERROR(INDEX(tblTasks[Due Date],5),"") | G10: =IFERROR(INDEX(tblTasks[Manual Status],5),"") | H10: =IFERROR(INDEX(tblTasks[Auto Health],5),"")
A11: Task | B11: =IFERROR(INDEX(tblTasks[Project ID],6),"") | C11: =IFERROR(INDEX(tblTasks[Task ID],6),"") | D11: =IFERROR(INDEX(tblTasks[Task Name],6),"") | E11: =IFERROR(INDEX(tblTasks[Assigned User],6),"") | F11: =IFERROR(INDEX(tblTasks[Due Date],6),"") | G11: =IFERROR(INDEX(tblTasks[Manual Status],6),"") | H11: =IFERROR(INDEX(tblTasks[Auto Health],6),"")
A12: Task | B12: =IFERROR(INDEX(tblTasks[Project ID],7),"") | C12: =IFERROR(INDEX(tblTasks[Task ID],7),"") | D12: =IFERROR(INDEX(tblTasks[Task Name],7),"") | E12: =IFERROR(INDEX(tblTasks[Assigned User],7),"") | F12: =IFERROR(INDEX(tblTasks[Due Date],7),"") | G12: =IFERROR(INDEX(tblTasks[Manual Status],7),"") | H12: =IFERROR(INDEX(tblTasks[Auto Health],7),"")
A13: Task | B13: =IFERROR(INDEX(tblTasks[Project ID],8),"") | C13: =IFERROR(INDEX(tblTasks[Task ID],8),"") | D13: =IFERROR(INDEX(tblTasks[Task Name],8),"") | E13: =IFERROR(INDEX(tblTasks[Assigned User],8),"") | F13: =IFERROR(INDEX(tblTasks[Due Date],8),"") | G13: =IFERROR(INDEX(tblTasks[Manual Status],8),"") | H13: =IFERROR(INDEX(tblTasks[Auto Health],8),"")
A14: Task | B14: =IFERROR(INDEX(tblTasks[Project ID],9),"") | C14: =IFERROR(INDEX(tblTasks[Task ID],9),"") | D14: =IFERROR(INDEX(tblTasks[Task Name],9),"") | E14: =IFERROR(INDEX(tblTasks[Assigned User],9),"") | F14: =IFERROR(INDEX(tblTasks[Due Date],9),"") | G14: =IFERROR(INDEX(tblTasks[Manual Status],9),"") | H14: =IFERROR(INDEX(tblTasks[Auto Health],9),"")
A15: Task | B15: =IFERROR(INDEX(tblTasks[Project ID],10),"") | C15: =IFERROR(INDEX(tblTasks[Task ID],10),"") | D15: =IFERROR(INDEX(tblTasks[Task Name],10),"") | E15: =IFERROR(INDEX(tblTasks[Assigned User],10),"") | F15: =IFERROR(INDEX(tblTasks[Due Date],10),"") | G15: =IFERROR(INDEX(tblTasks[Manual Status],10),"") | H15: =IFERROR(INDEX(tblTasks[Auto Health],10),"")
A16: Task | B16: =IFERROR(INDEX(tblTasks[Project ID],11),"") | C16: =IFERROR(INDEX(tblTasks[Task ID],11),"") | D16: =IFERROR(INDEX(tblTasks[Task Name],11),"") | E16: =IFERROR(INDEX(tblTasks[Assigned User],11),"") | F16: =IFERROR(INDEX(tblTasks[Due Date],11),"") | G16: =IFERROR(INDEX(tblTasks[Manual Status],11),"") | H16: =IFERROR(INDEX(tblTasks[Auto Health],11),"")
A17: Task | B17: =IFERROR(INDEX(tblTasks[Project ID],12),"") | C17: =IFERROR(INDEX(tblTasks[Task ID],12),"") | D17: =IFERROR(INDEX(tblTasks[Task Name],12),"") | E17: =IFERROR(INDEX(tblTasks[Assigned User],12),"") | F17: =IFERROR(INDEX(tblTasks[Due Date],12),"") | G17: =IFERROR(INDEX(tblTasks[Manual Status],12),"") | H17: =IFERROR(INDEX(tblTasks[Auto Health],12),"")
A18: Task | B18: =IFERROR(INDEX(tblTasks[Project ID],13),"") | C18: =IFERROR(INDEX(tblTasks[Task ID],13),"") | D18: =IFERROR(INDEX(tblTasks[Task Name],13),"") | E18: =IFERROR(INDEX(tblTasks[Assigned User],13),"") | F18: =IFERROR(INDEX(tblTasks[Due Date],13),"") | G18: =IFERROR(INDEX(tblTasks[Manual Status],13),"") | H18: =IFERROR(INDEX(tblTasks[Auto Health],13),"")
A19: Task | B19: =IFERROR(INDEX(tblTasks[Project ID],14),"") | C19: =IFERROR(INDEX(tblTasks[Task ID],14),"") | D19: =IFERROR(INDEX(tblTasks[Task Name],14),"") | E19: =IFERROR(INDEX(tblTasks[Assigned User],14),"") | F19: =IFERROR(INDEX(tblTasks[Due Date],14),"") | G19: =IFERROR(INDEX(tblTasks[Manual Status],14),"") | H19: =IFERROR(INDEX(tblTasks[Auto Health],14),"")
A20: Task | B20: =IFERROR(INDEX(tblTasks[Project ID],15),"") | C20: =IFERROR(INDEX(tblTasks[Task ID],15),"") | D20: =IFERROR(INDEX(tblTasks[Task Name],15),"") | E20: =IFERROR(INDEX(tblTasks[Assigned User],15),"") | F20: =IFERROR(INDEX(tblTasks[Due Date],15),"") | G20: =IFERROR(INDEX(tblTasks[Manual Status],15),"") | H20: =IFERROR(INDEX(tblTasks[Auto Health],15),"")
A21: Task | B21: =IFERROR(INDEX(tblTasks[Project ID],16),"") | C21: =IFERROR(INDEX(tblTasks[Task ID],16),"") | D21: =IFERROR(INDEX(tblTasks[Task Name],16),"") | E21: =IFERROR(INDEX(tblTasks[Assigned User],16),"") | F21: =IFERROR(INDEX(tblTasks[Due Date],16),"") | G21: =IFERROR(INDEX(tblTasks[Manual Status],16),"") | H21: =IFERROR(INDEX(tblTasks[Auto Health],16),"")
A22: Task | B22: =IFERROR(INDEX(tblTasks[Project ID],17),"") | C22: =IFERROR(INDEX(tblTasks[Task ID],17),"") | D22: =IFERROR(INDEX(tblTasks[Task Name],17),"") | E22: =IFERROR(INDEX(tblTasks[Assigned User],17),"") | F22: =IFERROR(INDEX(tblTasks[Due Date],17),"") | G22: =IFERROR(INDEX(tblTasks[Manual Status],17),"") | H22: =IFERROR(INDEX(tblTasks[Auto Health],17),"")
A23: Task | B23: =IFERROR(INDEX(tblTasks[Project ID],18),"") | C23: =IFERROR(INDEX(tblTasks[Task ID],18),"") | D23: =IFERROR(INDEX(tblTasks[Task Name],18),"") | E23: =IFERROR(INDEX(tblTasks[Assigned User],18),"") | F23: =IFERROR(INDEX(tblTasks[Due Date],18),"") | G23: =IFERROR(INDEX(tblTasks[Manual Status],18),"") | H23: =IFERROR(INDEX(tblTasks[Auto Health],18),"")
A24: Task | B24: =IFERROR(INDEX(tblTasks[Project ID],19),"") | C24: =IFERROR(INDEX(tblTasks[Task ID],19),"") | D24: =IFERROR(INDEX(tblTasks[Task Name],19),"") | E24: =IFERROR(INDEX(tblTasks[Assigned User],19),"") | F24: =IFERROR(INDEX(tblTasks[Due Date],19),"") | G24: =IFERROR(INDEX(tblTasks[Manual Status],19),"") | H24: =IFERROR(INDEX(tblTasks[Auto Health],19),"")
A25: Task | B25: =IFERROR(INDEX(tblTasks[Project ID],20),"") | C25: =IFERROR(INDEX(tblTasks[Task ID],20),"") | D25: =IFERROR(INDEX(tblTasks[Task Name],20),"") | E25: =IFERROR(INDEX(tblTasks[Assigned User],20),"") | F25: =IFERROR(INDEX(tblTasks[Due Date],20),"") | G25: =IFERROR(INDEX(tblTasks[Manual Status],20),"") | H25: =IFERROR(INDEX(tblTasks[Auto Health],20),"")

Sheet Kanban_View
A1: Kanban View
A2: Status board-style task view
A3: Home | B3: Dashboard | C3: Workspace | D3: Projects | E3: Tasks | F3: Issues | G3: Timesheets | H3: Reports | I3: Master
A5: Not Started | B5: In Progress | C5: Blocked | D5: In Review | E5: Completed
A6: =IFERROR(INDEX(FILTER(tblTasks[Task Name],tblTasks[Manual Status]=A$5),1),"") | B6: =IFERROR(INDEX(FILTER(tblTasks[Task Name],tblTasks[Manual Status]=B$5),1),"") | C6: =IFERROR(INDEX(FILTER(tblTasks[Task Name],tblTasks[Manual Status]=C$5),1),"") | D6: =IFERROR(INDEX(FILTER(tblTasks[Task Name],tblTasks[Manual Status]=D$5),1),"") | E6: =IFERROR(INDEX(FILTER(tblTasks[Task Name],tblTasks[Manual Status]=E$5),1),"")
A7: =IFERROR(INDEX(FILTER(tblTasks[Task Name],tblTasks[Manual Status]=A$5),2),"") | B7: =IFERROR(INDEX(FILTER(tblTasks[Task Name],tblTasks[Manual Status]=B$5),2),"") | C7: =IFERROR(INDEX(FILTER(tblTasks[Task Name],tblTasks[Manual Status]=C$5),2),"") | D7: =IFERROR(INDEX(FILTER(tblTasks[Task Name],tblTasks[Manual Status]=D$5),2),"") | E7: =IFERROR(INDEX(FILTER(tblTasks[Task Name],tblTasks[Manual Status]=E$5),2),"")
A8: =IFERROR(INDEX(FILTER(tblTasks[Task Name],tblTasks[Manual Status]=A$5),3),"") | B8: =IFERROR(INDEX(FILTER(tblTasks[Task Name],tblTasks[Manual Status]=B$5),3),"") | C8: =IFERROR(INDEX(FILTER(tblTasks[Task Name],tblTasks[Manual Status]=C$5),3),"") | D8: =IFERROR(INDEX(FILTER(tblTasks[Task Name],tblTasks[Manual Status]=D$5),3),"") | E8: =IFERROR(INDEX(FILTER(tblTasks[Task Name],tblTasks[Manual Status]=E$5),3),"")
A9: =IFERROR(INDEX(FILTER(tblTasks[Task Name],tblTasks[Manual Status]=A$5),4),"") | B9: =IFERROR(INDEX(FILTER(tblTasks[Task Name],tblTasks[Manual Status]=B$5),4),"") | C9: =IFERROR(INDEX(FILTER(tblTasks[Task Name],tblTasks[Manual Status]=C$5),4),"") | D9: =IFERROR(INDEX(FILTER(tblTasks[Task Name],tblTasks[Manual Status]=D$5),4),"") | E9: =IFERROR(INDEX(FILTER(tblTasks[Task Name],tblTasks[Manual Status]=E$5),4),"")
A10: =IFERROR(INDEX(FILTER(tblTasks[Task Name],tblTasks[Manual Status]=A$5),5),"") | B10: =IFERROR(INDEX(FILTER(tblTasks[Task Name],tblTasks[Manual Status]=B$5),5),"") | C10: =IFERROR(INDEX(FILTER(tblTasks[Task Name],tblTasks[Manual Status]=C$5),5),"") | D10: =IFERROR(INDEX(FILTER(tblTasks[Task Name],tblTasks[Manual Status]=D$5),5),"") | E10: =IFERROR(INDEX(FILTER(tblTasks[Task Name],tblTasks[Manual Status]=E$5),5),"")
A11: =IFERROR(INDEX(FILTER(tblTasks[Task Name],tblTasks[Manual Status]=A$5),6),"") | B11: =IFERROR(INDEX(FILTER(tblTasks[Task Name],tblTasks[Manual Status]=B$5),6),"") | C11: =IFERROR(INDEX(FILTER(tblTasks[Task Name],tblTasks[Manual Status]=C$5),6),"") | D11: =IFERROR(INDEX(FILTER(tblTasks[Task Name],tblTasks[Manual Status]=D$5),6),"") | E11: =IFERROR(INDEX(FILTER(tblTasks[Task Name],tblTasks[Manual Status]=E$5),6),"")
A12: =IFERROR(INDEX(FILTER(tblTasks[Task Name],tblTasks[Manual Status]=A$5),7),"") | B12: =IFERROR(INDEX(FILTER(tblTasks[Task Name],tblTasks[Manual Status]=B$5),7),"") | C12: =IFERROR(INDEX(FILTER(tblTasks[Task Name],tblTasks[Manual Status]=C$5),7),"") | D12: =IFERROR(INDEX(FILTER(tblTasks[Task Name],tblTasks[Manual Status]=D$5),7),"") | E12: =IFERROR(INDEX(FILTER(tblTasks[Task Name],tblTasks[Manual Status]=E$5),7),"")
